Workbook

Sheet Summary
A1: 17037 Field Failure Tally by Property — 2026-08-15 14:33 UTC
A2: Scope: devices on FW 17037, Installed=TRUE, excluding Production Inventory/Provisioned/Start groups. Source: ThingsBoard live scan.
A4: Property | B4: Total Failed | C4: Casualty (metered pre-FW) | D4: No Water | E4: Pre-existing dead | F4: Pulled meter (OLD tag) | G4: Unclassified | H4: Failed Cal | I4: Calibrating | J4: TI Silent | K4: HW Flag
A5: Auburn MHC | B5: =COUNTIF(Detail!$B$2:$B$88,$A5) | C5: =COUNTIFS(Detail!$B$2:$B$88,$A5,Detail!$E$2:$E$88,"Casualty (metered pre-FW)") | D5: =COUNTIFS(Detail!$B$2:$B$88,$A5,Detail!$E$2:$E$88,"No Water flagged") | E5: =COUNTIFS(Detail!$B$2:$B$88,$A5,Detail!$E$2:$E$88,"Pre-existing dead (never metered)") | F5: =COUNTIFS(Detail!$B$2:$B$88,$A5,Detail!$E$2:$E$88,"Pulled meter (OLD/REMOVED tag)") | G5: =COUNTIFS(Detail!$B$2:$B$88,$A5,Detail!$E$2:$E$88,"Unclassified") | H5: =COUNTIFS(Detail!$B$2:$B$88,$A5,Detail!$D$2:$D$88,"Failed Cal") | I5: =COUNTIFS(Detail!$B$2:$B$88,$A5,Detail!$D$2:$D$88,"Calibrating") | J5: =COUNTIFS(Detail!$B$2:$B$88,$A5,Detail!$D$2:$D$88,"TI Silent") | K5: =COUNTIFS(Detail!$B$2:$B$88,$A5,Detail!$J$2:$J$88,"Y")
A6: Aurora MHC | B6: =COUNTIF(Detail!$B$2:$B$88,$A6) | C6: =COUNTIFS(Detail!$B$2:$B$88,$A6,Detail!$E$2:$E$88,"Casualty (metered pre-FW)") | D6: =COUNTIFS(Detail!$B$2:$B$88,$A6,Detail!$E$2:$E$88,"No Water flagged") | E6: =COUNTIFS(Detail!$B$2:$B$88,$A6,Detail!$E$2:$E$88,"Pre-existing dead (never metered)") | F6: =COUNTIFS(Detail!$B$2:$B$88,$A6,Detail!$E$2:$E$88,"Pulled meter (OLD/REMOVED tag)") | G6: =COUNTIFS(Detail!$B$2:$B$88,$A6,Detail!$E$2:$E$88,"Unclassified") | H6: =COUNTIFS(Detail!$B$2:$B$88,$A6,Detail!$D$2:$D$88,"Failed Cal") | I6: =COUNTIFS(Detail!$B$2:$B$88,$A6,Detail!$D$2:$D$88,"Calibrating") | J6: =COUNTIFS(Detail!$B$2:$B$88,$A6,Detail!$D$2:$D$88,"TI Silent") | K6: =COUNTIFS(Detail!$B$2:$B$88,$A6,Detail!$J$2:$J$88,"Y")
A7: Azulejo | B7: =COUNTIF(Detail!$B$2:$B$88,$A7) | C7: =COUNTIFS(Detail!$B$2:$B$88,$A7,Detail!$E$2:$E$88,"Casualty (metered pre-FW)") | D7: =COUNTIFS(Detail!$B$2:$B$88,$A7,Detail!$E$2:$E$88,"No Water flagged") | E7: =COUNTIFS(Detail!$B$2:$B$88,$A7,Detail!$E$2:$E$88,"Pre-existing dead (never metered)") | F7: =COUNTIFS(Detail!$B$2:$B$88,$A7,Detail!$E$2:$E$88,"Pulled meter (OLD/REMOVED tag)") | G7: =COUNTIFS(Detail!$B$2:$B$88,$A7,Detail!$E$2:$E$88,"Unclassified") | H7: =COUNTIFS(Detail!$B$2:$B$88,$A7,Detail!$D$2:$D$88,"Failed Cal") | I7: =COUNTIFS(Detail!$B$2:$B$88,$A7,Detail!$D$2:$D$88,"Calibrating") | J7: =COUNTIFS(Detail!$B$2:$B$88,$A7,Detail!$D$2:$D$88,"TI Silent") | K7: =COUNTIFS(Detail!$B$2:$B$88,$A7,Detail!$J$2:$J$88,"Y")
A8: Broadway MHP DesMoines | B8: =COUNTIF(Detail!$B$2:$B$88,$A8) | C8: =COUNTIFS(Detail!$B$2:$B$88,$A8,Detail!$E$2:$E$88,"Casualty (metered pre-FW)") | D8: =COUNTIFS(Detail!$B$2:$B$88,$A8,Detail!$E$2:$E$88,"No Water flagged") | E8: =COUNTIFS(Detail!$B$2:$B$88,$A8,Detail!$E$2:$E$88,"Pre-existing dead (never metered)") | F8: =COUNTIFS(Detail!$B$2:$B$88,$A8,Detail!$E$2:$E$88,"Pulled meter (OLD/REMOVED tag)") | G8: =COUNTIFS(Detail!$B$2:$B$88,$A8,Detail!$E$2:$E$88,"Unclassified") | H8: =COUNTIFS(Detail!$B$2:$B$88,$A8,Detail!$D$2:$D$88,"Failed Cal") | I8: =COUNTIFS(Detail!$B$2:$B$88,$A8,Detail!$D$2:$D$88,"Calibrating") | J8: =COUNTIFS(Detail!$B$2:$B$88,$A8,Detail!$D$2:$D$88,"TI Silent") | K8: =COUNTIFS(Detail!$B$2:$B$88,$A8,Detail!$J$2:$J$88,"Y")
A9: CJ | B9: =COUNTIF(Detail!$B$2:$B$88,$A9) | C9: =COUNTIFS(Detail!$B$2:$B$88,$A9,Detail!$E$2:$E$88,"Casualty (metered pre-FW)") | D9: =COUNTIFS(Detail!$B$2:$B$88,$A9,Detail!$E$2:$E$88,"No Water flagged") | E9: =COUNTIFS(Detail!$B$2:$B$88,$A9,Detail!$E$2:$E$88,"Pre-existing dead (never metered)") | F9: =COUNTIFS(Detail!$B$2:$B$88,$A9,Detail!$E$2:$E$88,"Pulled meter (OLD/REMOVED tag)") | G9: =COUNTIFS(Detail!$B$2:$B$88,$A9,Detail!$E$2:$E$88,"Unclassified") | H9: =COUNTIFS(Detail!$B$2:$B$88,$A9,Detail!$D$2:$D$88,"Failed Cal") | I9: =COUNTIFS(Detail!$B$2:$B$88,$A9,Detail!$D$2:$D$88,"Calibrating") | J9: =COUNTIFS(Detail!$B$2:$B$88,$A9,Detail!$D$2:$D$88,"TI Silent") | K9: =COUNTIFS(Detail!$B$2:$B$88,$A9,Detail!$J$2:$J$88,"Y")
A10: Cactus Flower | B10: =COUNTIF(Detail!$B$2:$B$88,$A10) | C10: =COUNTIFS(Detail!$B$2:$B$88,$A10,Detail!$E$2:$E$88,"Casualty (metered pre-FW)") | D10: =COUNTIFS(Detail!$B$2:$B$88,$A10,Detail!$E$2:$E$88,"No Water flagged") | E10: =COUNTIFS(Detail!$B$2:$B$88,$A10,Detail!$E$2:$E$88,"Pre-existing dead (never metered)") | F10: =COUNTIFS(Detail!$B$2:$B$88,$A10,Detail!$E$2:$E$88,"Pulled meter (OLD/REMOVED tag)") | G10: =COUNTIFS(Detail!$B$2:$B$88,$A10,Detail!$E$2:$E$88,"Unclassified") | H10: =COUNTIFS(Detail!$B$2:$B$88,$A10,Detail!$D$2:$D$88,"Failed Cal") | I10: =COUNTIFS(Detail!$B$2:$B$88,$A10,Detail!$D$2:$D$88,"Calibrating") | J10: =COUNTIFS(Detail!$B$2:$B$88,$A10,Detail!$D$2:$D$88,"TI Silent") | K10: =COUNTIFS(Detail!$B$2:$B$88,$A10,Detail!$J$2:$J$88,"Y")
A11: Canada | B11: =COUNTIF(Detail!$B$2:$B$88,$A11) | C11: =COUNTIFS(Detail!$B$2:$B$88,$A11,Detail!$E$2:$E$88,"Casualty (metered pre-FW)") | D11: =COUNTIFS(Detail!$B$2:$B$88,$A11,Detail!$E$2:$E$88,"No Water flagged") | E11: =COUNTIFS(Detail!$B$2:$B$88,$A11,Detail!$E$2:$E$88,"Pre-existing dead (never metered)") | F11: =COUNTIFS(Detail!$B$2:$B$88,$A11,Detail!$E$2:$E$88,"Pulled meter (OLD/REMOVED tag)") | G11: =COUNTIFS(Detail!$B$2:$B$88,$A11,Detail!$E$2:$E$88,"Unclassified") | H11: =COUNTIFS(Detail!$B$2:$B$88,$A11,Detail!$D$2:$D$88,"Failed Cal") | I11: =COUNTIFS(Detail!$B$2:$B$88,$A11,Detail!$D$2:$D$88,"Calibrating") | J11: =COUNTIFS(Detail!$B$2:$B$88,$A11,Detail!$D$2:$D$88,"TI Silent") | K11: =COUNTIFS(Detail!$B$2:$B$88,$A11,Detail!$J$2:$J$88,"Y")
A12: Coleman Village | B12: =COUNTIF(Detail!$B$2:$B$88,$A12) | C12: =COUNTIFS(Detail!$B$2:$B$88,$A12,Detail!$E$2:$E$88,"Casualty (metered pre-FW)") | D12: =COUNTIFS(Detail!$B$2:$B$88,$A12,Detail!$E$2:$E$88,"No Water flagged") | E12: =COUNTIFS(Detail!$B$2:$B$88,$A12,Detail!$E$2:$E$88,"Pre-existing dead (never metered)") | F12: =COUNTIFS(Detail!$B$2:$B$88,$A12,Detail!$E$2:$E$88,"Pulled meter (OLD/REMOVED tag)") | G12: =COUNTIFS(Detail!$B$2:$B$88,$A12,Detail!$E$2:$E$88,"Unclassified") | H12: =COUNTIFS(Detail!$B$2:$B$88,$A12,Detail!$D$2:$D$88,"Failed Cal") | I12: =COUNTIFS(Detail!$B$2:$B$88,$A12,Detail!$D$2:$D$88,"Calibrating") | J12: =COUNTIFS(Detail!$B$2:$B$88,$A12,Detail!$D$2:$D$88,"TI Silent") | K12: =COUNTIFS(Detail!$B$2:$B$88,$A12,Detail!$J$2:$J$88,"Y")
A13: Crystal Acres MHC | B13: =COUNTIF(Detail!$B$2:$B$88,$A13) | C13: =COUNTIFS(Detail!$B$2:$B$88,$A13,Detail!$E$2:$E$88,"Casualty (metered pre-FW)") | D13: =COUNTIFS(Detail!$B$2:$B$88,$A13,Detail!$E$2:$E$88,"No Water flagged") | E13: =COUNTIFS(Detail!$B$2:$B$88,$A13,Detail!$E$2:$E$88,"Pre-existing dead (never metered)") | F13: =COUNTIFS(Detail!$B$2:$B$88,$A13,Detail!$E$2:$E$88,"Pulled meter (OLD/REMOVED tag)") | G13: =COUNTIFS(Detail!$B$2:$B$88,$A13,Detail!$E$2:$E$88,"Unclassified") | H13: =COUNTIFS(Detail!$B$2:$B$88,$A13,Detail!$D$2:$D$88,"Failed Cal") | I13: =COUNTIFS(Detail!$B$2:$B$88,$A13,Detail!$D$2:$D$88,"Calibrating") | J13: =COUNTIFS(Detail!$B$2:$B$88,$A13,Detail!$D$2:$D$88,"TI Silent") | K13: =COUNTIFS(Detail!$B$2:$B$88,$A13,Detail!$J$2:$J$88,"Y")
A14: Grand Valley Estates MHC | B14: =COUNTIF(Detail!$B$2:$B$88,$A14) | C14: =COUNTIFS(Detail!$B$2:$B$88,$A14,Detail!$E$2:$E$88,"Casualty (metered pre-FW)") | D14: =COUNTIFS(Detail!$B$2:$B$88,$A14,Detail!$E$2:$E$88,"No Water flagged") | E14: =COUNTIFS(Detail!$B$2:$B$88,$A14,Detail!$E$2:$E$88,"Pre-existing dead (never metered)") | F14: =COUNTIFS(Detail!$B$2:$B$88,$A14,Detail!$E$2:$E$88,"Pulled meter (OLD/REMOVED tag)") | G14: =COUNTIFS(Detail!$B$2:$B$88,$A14,Detail!$E$2:$E$88,"Unclassified") | H14: =COUNTIFS(Detail!$B$2:$B$88,$A14,Detail!$D$2:$D$88,"Failed Cal") | I14: =COUNTIFS(Detail!$B$2:$B$88,$A14,Detail!$D$2:$D$88,"Calibrating") | J14: =COUNTIFS(Detail!$B$2:$B$88,$A14,Detail!$D$2:$D$88,"TI Silent") | K14: =COUNTIFS(Detail!$B$2:$B$88,$A14,Detail!$J$2:$J$88,"Y")
A15: Highlands MHC | B15: =COUNTIF(Detail!$B$2:$B$88,$A15) | C15: =COUNTIFS(Detail!$B$2:$B$88,$A15,Detail!$E$2:$E$88,"Casualty (metered pre-FW)") | D15: =COUNTIFS(Detail!$B$2:$B$88,$A15,Detail!$E$2:$E$88,"No Water flagged") | E15: =COUNTIFS(Detail!$B$2:$B$88,$A15,Detail!$E$2:$E$88,"Pre-existing dead (never metered)") | F15: =COUNTIFS(Detail!$B$2:$B$88,$A15,Detail!$E$2:$E$88,"Pulled meter (OLD/REMOVED tag)") | G15: =COUNTIFS(Detail!$B$2:$B$88,$A15,Detail!$E$2:$E$88,"Unclassified") | H15: =COUNTIFS(Detail!$B$2:$B$88,$A15,Detail!$D$2:$D$88,"Failed Cal") | I15: =COUNTIFS(Detail!$B$2:$B$88,$A15,Detail!$D$2:$D$88,"Calibrating") | J15: =COUNTIFS(Detail!$B$2:$B$88,$A15,Detail!$D$2:$D$88,"TI Silent") | K15: =COUNTIFS(Detail!$B$2:$B$88,$A15,Detail!$J$2:$J$88,"Y")
A16: Hillview MHC | B16: =COUNTIF(Detail!$B$2:$B$88,$A16) | C16: =COUNTIFS(Detail!$B$2:$B$88,$A16,Detail!$E$2:$E$88,"Casualty (metered pre-FW)") | D16: =COUNTIFS(Detail!$B$2:$B$88,$A16,Detail!$E$2:$E$88,"No Water flagged") | E16: =COUNTIFS(Detail!$B$2:$B$88,$A16,Detail!$E$2:$E$88,"Pre-existing dead (never metered)") | F16: =COUNTIFS(Detail!$B$2:$B$88,$A16,Detail!$E$2:$E$88,"Pulled meter (OLD/REMOVED tag)") | G16: =COUNTIFS(Detail!$B$2:$B$88,$A16,Detail!$E$2:$E$88,"Unclassified") | H16: =COUNTIFS(Detail!$B$2:$B$88,$A16,Detail!$D$2:$D$88,"Failed Cal") | I16: =COUNTIFS(Detail!$B$2:$B$88,$A16,Detail!$D$2:$D$88,"Calibrating") | J16: =COUNTIFS(Detail!$B$2:$B$88,$A16,Detail!$D$2:$D$88,"TI Silent") | K16: =COUNTIFS(Detail!$B$2:$B$88,$A16,Detail!$J$2:$J$88,"Y")
... A36: Virginia Beach | B36: =COUNTIF(Detail!$B$2:$B$88,$A36) | C36: =COUNTIFS(Detail!$B$2:$B$88,$A36,Detail!$E$2:$E$88,"Casualty (metered pre-FW)") | D36: =COUNTIFS(Detail!$B$2:$B$88,$A36,Detail!$E$2:$E$88,"No Water flagged") | E36: =COUNTIFS(Detail!$B$2:$B$88,$A36,Detail!$E$2:$E$88,"Pre-existing dead (never metered)") | F36: =COUNTIFS(Detail!$B$2:$B$88,$A36,Detail!$E$2:$E$88,"Pulled meter (OLD/REMOVED tag)") | G36: =COUNTIFS(Detail!$B$2:$B$88,$A36,Detail!$E$2:$E$88,"Unclassified") | H36: =COUNTIFS(Detail!$B$2:$B$88,$A36,Detail!$D$2:$D$88,"Failed Cal") | I36: =COUNTIFS(Detail!$B$2:$B$88,$A36,Detail!$D$2:$D$88,"Calibrating") | J36: =COUNTIFS(Detail!$B$2:$B$88,$A36,Detail!$D$2:$D$88,"TI Silent") | K36: =COUNTIFS(Detail!$B$2:$B$88,$A36,Detail!$J$2:$J$88,"Y")
A37: TOTAL | B37: =SUM(B5:B36) | C37: =SUM(C5:C36) | D37: =SUM(D5:D36) | E37: =SUM(E5:E36) | F37: =SUM(F5:F36) | G37: =SUM(G5:G36) | H37: =SUM(H5:H36) | I37: =SUM(I5:I36) | ... K37: =SUM(K5:K36)

Sheet Detail
A1: Device ID | B1: Property | C1: Apartment | D1: State | E1: Category | F1: No Water | G1: Gain | H1: Pipe Type | I1: Pipe Size | J1: HW Flag | K1: spiInitFail
A2: 79466692 | B2: Auburn MHC | C2: 3 | D2: Failed Cal | E2: Pre-existing dead (never metered) | F2: false | G2: 55 | H2: L | I2: ½ | K2: 0
A3: 70261761 | B3: Aurora MHC | C3: 159 | D3: Failed Cal | E3: Casualty (metered pre-FW) | F3: false | G3: 41 | H3: M | I3: ½ | K3: 0
A4: 77057885 | B4: Aurora MHC | C4: 33 | D4: Failed Cal | E4: Casualty (metered pre-FW) | F4: false | G4: 55 | H4: X | I4: ½ | K4: 0
A5: 72717897 | B5: Azulejo | C5: 1502 | D5: Metering | E5: Casualty (metered pre-FW) | F5: false | G5: 32 | H5: X | I5: ¾ | J5: Y | K5: 5819
A6: 75367704 | B6: Broadway MHP DesMoines | C6: 4 | D6: Failed Cal | E6: Casualty (metered pre-FW) | F6: false | G6: 26 | H6: X | I6: ½ | K6: 0
A7: 75374122 | B7: CJ | C7: 116 | D7: TI Silent | E7: Casualty (metered pre-FW) | F7: false | G7: 0 | H7: L | I7: 1 | K7: 0
A8: 75362382 | B8: Cactus Flower | C8: 9 and Laundry | D8: Failed Cal | E8: Casualty (metered pre-FW) | F8: false | G8: 55 | H8: L | I8: ¾ | K8: 0
A9: 77054759 | B9: Canada | C9: D1TC | D9: Failed Cal | E9: Casualty (metered pre-FW) | F9: false | G9: 32 | H9: X | I9: ½ | K9: 0
A10: 77061481 | B10: Canada | C10: B18TC | D10: Failed Cal | E10: Casualty (metered pre-FW) | F10: false | G10: 55 | H10: M | I10: ½ | K10: 0
A11: 70261902 | B11: Coleman Village | C11: 179 | D11: Failed Cal | E11: No Water flagged | F11: true | G11: 55 | H11: X | I11: ¾ | K11: 0
A12: 70265408 | B12: Crystal Acres MHC | C12: 7-OLD | D12: TI Silent | E12: Pulled meter (OLD/REMOVED tag) | F12: false | G12: 0 | H12: P | I12: ¾ | J12: Y | K12: 0
A13: 72379413 | B13: Crystal Acres MHC | C13: 16-OLD | D13: Failed Cal | E13: Pulled meter (OLD/REMOVED tag) | F13: false | G13: 55 | H13: X | I13: ¾ | K13: 0
A14: 72384678 | B14: Crystal Acres MHC | C14: 13 | D14: TI Silent | E14: Unclassified | F14: false | G14: 0 | H14: X | I14: ¾ | K14: 0
A15: 75360113 | B15: Grand Valley Estates MHC | C15: 10-SHENNADOH-DR | D15: Failed Cal | E15: No Water flagged | F15: true | G15: 55 | H15: X | I15: ¾ | K15: 0
A16: 75364495 | B16: Grand Valley Estates MHC | C16: 23-DOUBLETREE-CT | D16: Failed Cal | E16: No Water flagged | F16: true | G16: 55 | H16: X | I16: ¾ | K16: 0
A17: 75365286 | B17: Grand Valley Estates MHC | C17: 8-SHENNADOH-DR | D17: Failed Cal | E17: No Water flagged | F17: true | G17: 53 | H17: X | I17: ¾ | K17: 0
A18: 75365757 | B18: Grand Valley Estates MHC | C18: 13-SHENNADOH-DR | D18: Failed Cal | E18: No Water flagged | F18: true | G18: 55 | H18: X | I18: ¾ | K18: 0
A19: 75366441 | B19: Grand Valley Estates MHC | C19: 26-DOUBLETREE-CT | D19: Failed Cal | E19: No Water flagged | F19: true | G19: 55 | H19: X | I19: ¾ | K19: 0
A20: 75366607 | B20: Grand Valley Estates MHC | C20: 15-SHENNADOH-DR | D20: Failed Cal | E20: No Water flagged | F20: true | G20: 55 | H20: X | I20: ¾ | K20: 0
A21: 75366805 | B21: Grand Valley Estates MHC | C21: 7-SHENNADOH-DR | D21: Failed Cal | E21: No Water flagged | F21: true | G21: 55 | H21: X | I21: ¾ | K21: 0
A22: 75367852 | B22: Grand Valley Estates MHC | C22: 19-SHENNADOH-DR | D22: Failed Cal | E22: No Water flagged | F22: true | G22: 55 | H22: X | I22: ¾ | K22: 0
A23: 75368298 | B23: Grand Valley Estates MHC | C23: 20-SHENNADOH-DR | D23: Failed Cal | E23: No Water flagged | F23: true | G23: 55 | H23: X | I23: ¾ | K23: 0
A24: 75369007 | B24: Grand Valley Estates MHC | C24: 5-DOUBLETREE-DR | D24: Calibrating | E24: Unclassified | F24: false | G24: 40 | H24: X | I24: ¾ | K24: 0
... A47: 72391756 | B47: Ibiza Village2 | C47: 2-OLD | D47: Failed Cal | E47: Pulled meter (OLD/REMOVED tag) | F47: false | G47: 55 | H47: M | I47: 1 | K47: 0
A48: 70263080 | B48: John Alexander ADU 5YR | D48: Failed Cal | E48: Casualty (metered pre-FW) | F48: false | G48: 41 | H48: X | I48: ¾ | K48: 0
A49: 70260011 | B49: Kingsbrook MHC | C49: 596MI | D49: TI Silent | E49: Casualty (metered pre-FW) | F49: false | G49: 0 | H49: X | I49: ¾ | K49: 0
A50: 75367050 | B50: Kingsbrook MHC | C50: 778AM | D50: Failed Cal | E50: Pre-existing dead (never metered) | F50: false | G50: 55 | H50: M | I50: ½ | K50: 0
A51: 72380866 | B51: Lafountaine MHC | C51: 125CC | D51: Failed Cal | E51: Casualty (metered pre-FW) | F51: false | G51: 55 | H51: X | I51: ¾ | K51: 0
A52: 72723051 | B52: Little Acres MHC | C52: 9 | D52: Calibrating | E52: Unclassified | F52: false | G52: 40 | H52: P | I52: ½ | K52: 0
A53: 70266901 | B53: Maple Run MHP | C53: 11 | D53: Failed Cal | E53: Casualty (metered pre-FW) | F53: false | G53: 55 | H53: P | I53: ¾ | K53: 0
A54: 72720776 | B54: Mountaineer Village MHC | D54: Failed Cal | E54: Casualty (metered pre-FW) | F54: false | G54: 55 | H54: X | I54: ¾ | K54: 0
A55: 77053348 | B55: Oak Forest Estate MHC | C55: 2-REMOVED | D55: Failed Cal | E55: Pulled meter (OLD/REMOVED tag) | F55: false | G55: 55 | H55: P | I55: ¾ | K55: 0
A56: 70266620 | B56: PW2 | C56: 3124LINDA | D56: Failed Cal | E56: No Water flagged | F56: true | G56: 38 | H56: X | I56: ¾ | K56: 0
A57: 79461560 | B57: Paola MHC | C57: 23 | D57: Metering | E57: Unclassified | F57: false | G57: 38 | H57: X | I57: ½ | K57: 0
A58: 70270440 | B58: Parker MHC | C58: 11 | D58: Failed Cal | E58: Casualty (metered pre-FW) | F58: false | G58: 55 | H58: X | I58: ¾ | K58: 0
A59: 77059808 | B59: Parkview MHP | C59: C53OFFICE | D59: Failed Cal | E59: Casualty (metered pre-FW) | F59: false | G59: 55 | H59: X | I59: ½ | K59: 0
A60: 75363810 | B60: Pleasant Acres | C60: 33-OLD | D60: Failed Cal | E60: Pulled meter (OLD/REMOVED tag) | F60: false | G60: 55 | H60: X | I60: ¾ | K60: 0
A61: 75371151 | B61: River Bend | C61: 23 | D61: Failed Cal | E61: Casualty (metered pre-FW) | F61: false | G61: 29 | H61: X | I61: ¾ | K61: 0
A62: 75362978 | B62: Roosevelt MHC | C62: 140 | D62: Failed Cal | E62: Casualty (metered pre-FW) | F62: false | G62: 47 | H62: X | I62: ¾ | K62: 0
...
